开始训练...
训练集数据处理。。。。
=============
验证集数据处理。。。。。
=============
0
Traceback (most recent call last):
  File "D:/Users/Admin/PycharmProjects/PyCharm_Projects/Deep_learning/cat_dog/model_training02.py", line 111, in <module>
    train(model, EPOCH_NLM, opt)
  File "D:/Users/Admin/PycharmProjects/PyCharm_Projects/Deep_learning/cat_dog/model_training02.py", line 37, in train
    logits = model(img)
  File "D:\Users\Admin\Python37\lib\site-packages\paddle\fluid\dygraph\layers.py", line 902, in __call__
    outputs = self.forward(*inputs, **kwargs)
  File "D:\Users\Admin\PycharmProjects\PyCharm_Projects\Deep_learning\cat_dog\LeNet.py", line 41, in forward
    input = paddle.reshape(input, shape=[1, 3, 100, 100])  # 转换维度
  File "D:\Users\Admin\Python37\lib\site-packages\paddle\tensor\manipulation.py", line 1582, in reshape
    return paddle.fluid.layers.reshape(x=x, shape=shape, name=name)
  File "D:\Users\Admin\Python37\lib\site-packages\paddle\fluid\layers\nn.py", line 6142, in reshape
    out, _ = core.ops.reshape2(x, None, 'shape', shape)
ValueError: (InvalidArgument) The 'shape' in ReshapeOp is invalid. The input tensor X'size must be equal to the capacity of 'shape'. But received X's shape = [10, 3, 100, 100], X's size = 300000, 'shape' is [1, 3, 100, 100], the capacity of 'shape' is 30000.
  [Hint: Expected capacity == in_size, but received capacity:30000 != in_size:300000.] (at C:/home/workspace/Paddle_release/paddle/fluid/operators/reshape_op.cc:222)
  [operator < reshape2 > error]
开始训练...
训练集数据处理。。。。
=============
验证集数据处理。。。。。
=============
0
epoch: 0, batch_id: 0, loss is：0.8294
[validation] accuracy 0.6250, loss 0.4464
1
epoch: 1, batch_id: 0, loss is：0.2724
[validation] accuracy 0.7750, loss 0.2063
2
epoch: 2, batch_id: 0, loss is：0.1573
[validation] accuracy 1.0000, loss 0.1132
3
epoch: 3, batch_id: 0, loss is：0.0984
[validation] accuracy 1.0000, loss 0.0743
4
epoch: 4, batch_id: 0, loss is：0.0667
[validation] accuracy 1.0000, loss 0.0566
5
epoch: 5, batch_id: 0, loss is：0.0511
[validation] accuracy 1.0000, loss 0.0464
6
epoch: 6, batch_id: 0, loss is：0.0417
[validation] accuracy 1.0000, loss 0.0401
7
epoch: 7, batch_id: 0, loss is：0.0363
[validation] accuracy 1.0000, loss 0.0356
8
epoch: 8, batch_id: 0, loss is：0.0325
[validation] accuracy 1.0000, loss 0.0321
9
epoch: 9, batch_id: 0, loss is：0.0295
[validation] accuracy 1.0000, loss 0.0294
D:\Users\Admin\Python37\lib\site-packages\paddle\nn\layer\norm.py:641: UserWarning: When training, we now always track global mean and variance.
  "When training, we now always track global mean and variance.")
